<?xml version="1.0"?>
<robot xmlns:xacro="http://www.ros.org/wiki/xacro" name="asrs_robot">

  <!-- Properties -->
  <xacro:property name="PI" value="3.14159265359" />

  <!-- ARM LINKS -->
  <link name="world"/>

  <link name="base_link">
    <inertial>
      <origin xyz="-0.00049298 0.038467 0.059588" rpy="0 0 0" />
      <mass value="0.51487" />
      <inertia ixx="0.00097956" ixy="8.6139e-07" ixz="-4.2275e-06" iyy="0.00063322" iyz="-6.2879e-06" izz="0.0014458" />
    </inertial>
    <visual>
      <geometry>
        <mesh filename="package://my_robot_arm/meshes/link_1.STL"/>
      </geometry>
      <material name="">
        <color rgba="0.0 1.0 0.0 1.0"/>
      </material>
    </visual>
    <collision>
      <geometry>
        <mesh filename="package://my_robot_arm/meshes/link_1.STL"/>
      </geometry>
    </collision>
  </link>

  <link name="shoulder_link">
    <inertial>
      <origin xyz="3.3268e-05 0.038546 0.03493" rpy="0 0 0" />
      <mass value="0.34286" />
      <inertia ixx="0.0002982" ixy="-1.5865e-08" ixz="2.5289e-10" iyy="0.00012652" iyz="1.9537e-06" izz="0.0002767" />
    </inertial>
    <visual>
      <geometry>
        <mesh filename="package://my_robot_arm/meshes/link_2.STL"/>
      </geometry>
      <material name="">
        <color rgba="0.0 0.0 1.0 1.0"/>
      </material>
    </visual>
    <collision>
      <geometry>
        <mesh filename="package://my_robot_arm/meshes/link_2.STL"/>
      </geometry>
    </collision>
  </link>

  <link name="elbow_link">
    <inertial>
      <origin xyz="-0.00083473 -0.0061303 0.14093" rpy="0 0 0" />
      <mass value="0.64592" />
      <inertia ixx="0.00080618" ixy="-8.1896e-10" ixz="6.6639e-09" iyy="0.00073543" iyz="2.8682e-05" izz="0.00026191" />
    </inertial>
    <visual>
      <geometry>
        <mesh filename="package://my_robot_arm/meshes/link_3.STL"/>
      </geometry>
      <material name="">
        <color rgba="0.0 0.0 1.0 1.0"/>
      </material>
    </visual>
    <collision>
      <geometry>
        <mesh filename="package://my_robot_arm/meshes/link_3.STL"/>
      </geometry>
    </collision>
  </link>

  <link name="wrist1_link">
    <inertial>
      <origin xyz="0.00015398 -0.00014321 0.070552" rpy="0 0 0" />
      <mass value="0.082446" />
      <inertia ixx="7.1121e-05" ixy="-1.5741e-09" ixz="3.4653e-06" iyy="7.2808e-05" iyz="5.6573e-09" izz="1.4796e-05" />
    </inertial>
    <visual>
      <geometry>
        <mesh filename="package://my_robot_arm/meshes/link_4.STL"/>
      </geometry>
      <material name="">
        <color rgba="0.0 0.0 1.0 1.0"/>
      </material>
    </visual>
    <collision>
      <geometry>
        <mesh filename="package://my_robot_arm/meshes/link_4.STL"/>
      </geometry>
    </collision>
  </link>

  <!-- ARM JOINTS -->
  <joint name="world_to_baselink" type="revolute">
    <parent link="world"/>
    <child link="base_link"/>
    <origin xyz="0 0 0" rpy="0 0 0"/>
    <axis xyz="0 0 1"/>
    <limit lower="-${PI}" upper="${PI}" effort="50.0" velocity="1.0"/>
  </joint>

  <joint name="base_to_shoulder" type="revolute">
    <parent link="base_link"/>
    <child link="shoulder_link"/>
    <origin xyz="0 0 0.0863" rpy="0 0 -0.013059"/>
    <axis xyz="0 0 1"/>
    <limit lower="-${PI}" upper="${PI}" effort="30.0" velocity="1.0"/>
  </joint>

  <joint name="shoulder_to_elbow" type="revolute">
    <parent link="shoulder_link"/>
    <child link="elbow_link"/>
    <origin xyz="0 0 0.07095" rpy="0 0 0"/>
    <axis xyz="-1.0 0.0 0"/>
    <limit lower="-${PI/4}" upper="${PI/4}" effort="30.0" velocity="1.0"/>
  </joint>

  <joint name="elbow_to_wrist1" type="revolute">
    <parent link="elbow_link"/>
    <child link="wrist1_link"/>
    <origin xyz="0.0083376 -0.030916 0.24181" rpy="0.96329 0.012835 0.018459"/>
    <axis xyz="1.0 0.0 0"/>
    <limit lower="-${PI/4}" upper="${PI/4}" effort="20.0" velocity="1.0"/>
  </joint>


  <!-- GRIPPER INTEGRATION -->
  <!-- 1. Attach gripper fixture to the wrist -->
  <link name="gripper_fixture" />
  <joint name="wrist1_to_gripper_fixture" type="fixed">
    <parent link="wrist1_link"/>
    <child link="gripper_fixture"/>
    <origin xyz="-0.02866 0.0 0.12448" rpy="0 0 0"/>
  </joint>

  <!-- 2. Gripper Base (equivalent to "base" in the reference, renamed to avoid confusion) -->
  <link name="gripper_base">
    <inertial>
      <origin xyz="-0.00725047 0.02613263 0.01375543" rpy="0 0 0"/>
      <mass value="0.02053906"/>
      <inertia ixx="4.87174e-06" ixy="-9.44979e-07" ixz="-2.96105e-07"
               iyy="2.87148e-06" iyz="-8.81547e-07" izz="5.79458e-06"/>
    </inertial>
    <visual>
      <origin xyz="0 0 0" rpy="0 0 0"/>
      <geometry>
        <mesh filename="package://my_robot_arm/meshes/gripper_base.STL"/>
      </geometry>
      <material name="">
        <color rgba="0.792157 0.819608 0.933333 1"/>
      </material>
    </visual>
    <collision>
      <origin xyz="0 0 0" rpy="0 0 0"/>
      <geometry>
        <mesh filename="package://my_robot_arm/meshes/gripper_base.STL"/>
      </geometry>
    </collision>
  </link>

  <!-- Fixed joint from fixture to gripper base -->
  <joint name="fixture_to_gripper_base" type="fixed">
    <parent link="gripper_fixture"/>
    <child link="gripper_base"/>
    <origin xyz="-0.007 -0.0487 -0.0175" rpy="0 0 0"/>
  </joint>

  <!-- 3. Gripper Driver -->
  <link name="gripper_driver">
    <inertial>
      <origin xyz="6.23832e-06 -0.00569766 -0.00181818" rpy="0 0 0"/>
      <mass value="0.00256586"/>
      <inertia ixx="3.58255e-07" ixy="-3.79614e-08" ixz="4.59458e-22"
               iyy="9.47498e-08" iyz="4.28715e-21" izz="4.46163e-07"/>
    </inertial>
    <visual>
      <origin xyz="0 0 0" rpy="0 0 0"/>
      <geometry>
        <mesh filename="package://my_robot_arm/meshes/driver.STL"/>
      </geometry>
      <material name="">
        <color rgba="0.792157 0.819608 0.933333 1"/>
      </material>
    </visual>
    <collision>
      <origin xyz="0 0 0" rpy="0 0 0"/>
      <geometry>
        <mesh filename="package://my_robot_arm/meshes/driver.STL"/>
      </geometry>
    </collision>
  </link>

  <!-- Fixed joint connecting gripper_base to gripper_driver -->
  <joint name="gripper_base_to_driver" type="fixed">
    <parent link="gripper_base"/>
    <child link="gripper_driver"/>
    <origin xyz="-0.018617 0.020144 -0.00018182" rpy="0 0 0"/>
    <axis xyz="0 0 -1"/>
  </joint>

  <!-- 4. Left Finger -->
  <link name="left_finger">
    <inertial>
      <origin xyz="0.0038036 -0.0330606 -0.00425002" rpy="0 0 0"/>
      <mass value="0.00539747"/>
      <inertia ixx="1.64723e-06" ixy="2.53321e-07" ixz="1.39877e-11"
               iyy="1.31673e-07" iyz="-1.07568e-12" izz="1.71391e-06"/>
    </inertial>
    <visual>
      <origin xyz="0 0 0" rpy="0 0 0"/>
      <geometry>
        <mesh filename="package://my_robot_arm/meshes/left_finger.STL"/>
      </geometry>
      <material name="">
        <color rgba="0.792157 0.819608 0.933333 1"/>
      </material>
    </visual>
    <collision>
      <origin xyz="0 0 0" rpy="0 0 0"/>
      <geometry>
        <mesh filename="package://my_robot_arm/meshes/left_finger.STL"/>
      </geometry>
    </collision>
  </link>

  <!-- Joint connecting gripper_driver to left_finger -->
  <joint name="driver_to_left_finger" type="fixed">
    <parent link="gripper_driver"/>
    <child link="left_finger"/>
    <origin xyz="-0.00060087 -0.024016 0.0086818" rpy="0 0 0"/>
    <axis xyz="0 0 1"/>
    <mimic joint="gripper_base_to_driver" multiplier="1" offset="0"/>
  </joint>

  <!-- 5. Gripper Driven -->
  <link name="gripper_driven">
    <inertial>
      <origin xyz="6.17331e-05 -0.0056108 -0.00181818" rpy="0 0 0"/>
      <mass value="0.00264161"/>
      <inertia ixx="3.58233e-07" ixy="4.11845e-08" ixz="-3.77601e-22"
               iyy="9.60511e-08" iyz="3.20741e-21" izz="4.47240e-07"/>
    </inertial>
    <visual>
      <origin xyz="0 0 0" rpy="0 0 0"/>
      <geometry>
        <mesh filename="package://my_robot_arm/meshes/driven.STL"/>
      </geometry>
      <material name="">
        <color rgba="0.792157 0.819608 0.933333 1"/>
      </material>
    </visual>
    <collision>
      <origin xyz="0 0 0" rpy="0 0 0"/>
      <geometry>
        <mesh filename="package://my_robot_arm/meshes/driven.STL"/>
      </geometry>
    </collision>
  </link>

  <!-- Fixed joint connecting gripper_base to gripper_driven -->
  <joint name="gripper_base_to_driven" type="fixed">
    <parent link="gripper_base"/>
    <child link="gripper_driven"/>
    <origin xyz="0.0082832 0.020144 -0.00018182" rpy="0 0 0"/>
    <axis xyz="0 0 -1"/>
    <mimic joint="gripper_base_to_driver" multiplier="-1" offset="0"/>
  </joint>

  <!-- 6. Right Finger -->
  <link name="right_finger">
    <inertial>
      <origin xyz="-0.00349952 -0.03309417 0.00425002" rpy="0 0 0"/>
      <mass value="0.00539747"/>
      <inertia ixx="1.65176e-06" ixy="-2.39347e-07" ixz="1.39772e-11"
               iyy="1.27144e-07" iyz="1.20460e-12" izz="1.71391e-06"/>
    </inertial>
    <visual>
      <origin xyz="0 0 0" rpy="0 0 0"/>
      <geometry>
        <mesh filename="package://my_robot_arm/meshes/right_finger.STL"/>
      </geometry>
      <material name="">
        <color rgba="0.792157 0.819608 0.933333 1"/>
      </material>
    </visual>
    <collision>
      <origin xyz="0 0 0" rpy="0 0 0"/>
      <geometry>
        <mesh filename="package://my_robot_arm/meshes/right_finger.STL"/>
      </geometry> 
    </collision>
  </link>

  <!-- Joint connecting gripper_driven to right_finger -->
  <joint name="driven_to_right_finger" type="fixed">
    <parent link="gripper_driven"/>
    <child link="right_finger"/>
    <origin xyz="0.00094581 -0.023995 0.00018182" rpy="0 0 0"/>
    <axis xyz="0 0 1"/>
    <mimic joint="gripper_base_to_driver" multiplier="-0.8" offset="0"/>
  </joint>

  <!-- 7. Left Knuckle -->
  <link name="left_knuckle">
    <inertial>
      <origin xyz="-0.0017363 -0.015402 0.0044318" rpy="0 0 0"/>
      <mass value="0.0015975"/>
      <inertia ixx="2.0335e-07" ixy="-2.2104e-08" ixz="2.3011e-22"
               iyy="9.7567e-09" iyz="2.0614e-21" izz="2.0885e-07"/>
    </inertial>
    <visual>
      <origin xyz="0 0 0" rpy="0 0 0"/>
      <geometry>
        <mesh filename="package://my_robot_arm/meshes/left_knuckle.STL"/>
      </geometry>
      <material name="">
        <color rgba="0.79216 0.81961 0.93333 1"/>
      </material>
    </visual>
    <collision>
      <origin xyz="0 0 0" rpy="0 0 0"/>
      <geometry>
        <mesh filename="package://my_robot_arm/meshes/left_knuckle.STL"/>
      </geometry>
    </collision>
  </link>

  <!-- Joint connecting gripper_base to left_knuckle -->
  <joint name="gripper_base_to_left_knuckle" type="fixed">
    <parent link="gripper_base"/>
    <child link="left_knuckle"/>
    <origin xyz="-0.0097168 0.00014418 -0.00018182" rpy="0 0 0"/>
    <axis xyz="0 0 1"/>
    <mimic joint="gripper_base_to_driver" multiplier="-1" offset="0"/>
  </joint>

  <!-- 8. Right Knuckle -->
  <link name="right_knuckle">
    <inertial>
      <origin xyz="0 0 0" rpy="0 0 0"/>
      <mass value="0"/>
      <inertia ixx="0" ixy="0" ixz="0" iyy="0" iyz="0" izz="0"/>
    </inertial>
    <visual>
      <origin xyz="0 0 0" rpy="0 0 0"/>
      <geometry>
        <mesh filename="package://my_robot_arm/meshes/right_knuckle.STL"/>
      </geometry>
      <material name="">
        <color rgba="1 1 1 1"/>
      </material>
    </visual>
    <collision>
      <origin xyz="0 0 0" rpy="0 0 0"/>
      <geometry>
        <mesh filename="package://my_robot_arm/meshes/right_knuckle.STL"/>
      </geometry>
    </collision>
  </link>

  <!-- Joint connecting gripper_base to right_knuckle -->
  <joint name="gripper_base_to_right_knuckle" type="fixed">
    <parent link="gripper_base"/>
    <child link="right_knuckle"/>
    <origin xyz="0 0 -0.00018182" rpy="0 0 0"/>
    <axis xyz="0 0 1"/>
    <mimic joint="gripper_base_to_driver" multiplier="1" offset="0"/>
  </joint>

</robot>
